Workbook

Sheet ملخص
A1: فهرس قناة رياض الجنة (م. محمود علي)
A2: الأعداد محسوبة بالمعادلات من ورقة «الفهرس العام». لكل تصنيف ورقة مستقلة، ويمكن التصفية والبحث من رأس كل عمود.
A4: التصنيف | B4: السلسلة | C4: عدد المواد
A5: الاقتصاد الإسلامي | C5: =COUNTIF('الفهرس العام'!$B$2:$B$2508,A5)
B6: شرح مقدمة في الاقتصاد الإسلامي | C6: =COUNTIFS('الفهرس العام'!$B$2:$B$2508,"الاقتصاد الإسلامي",'الفهرس العام'!$C$2:$C$2508,B6)
B7: شرح كتاب أربعون قاعدة في فقه معاملات الأسواق | C7: =COUNTIFS('الفهرس العام'!$B$2:$B$2508,"الاقتصاد الإسلامي",'الفهرس العام'!$C$2:$C$2508,B7)
B8: استشارات اقتصادية | C8: =COUNTIFS('الفهرس العام'!$B$2:$B$2508,"الاقتصاد الإسلامي",'الفهرس العام'!$C$2:$C$2508,B8)
B9: النشرة الدورية للاقتصاد الإسلامي حول العالم | C9: =COUNTIFS('الفهرس العام'!$B$2:$B$2508,"الاقتصاد الإسلامي",'الفهرس العام'!$C$2:$C$2508,B9)
B10: محاضرات في الاقتصاد الإسلامي | C10: =COUNTIFS('الفهرس العام'!$B$2:$B$2508,"الاقتصاد الإسلامي",'الفهرس العام'!$C$2:$C$2508,B10)
B11: شرح أصول فقه الشركات | C11: =COUNTIFS('الفهرس العام'!$B$2:$B$2508,"الاقتصاد الإسلامي",'الفهرس العام'!$C$2:$C$2508,B11)
B12: ندوات ومحاضرات عامة | C12: =COUNTIFS('الفهرس العام'!$B$2:$B$2508,"الاقتصاد الإسلامي",'الفهرس العام'!$C$2:$C$2508,B12)
A13: دورة ما لا يسع المسلمة جهله | C13: =COUNTIF('الفهرس العام'!$B$2:$B$2508,A13)
B14: دورة ما لا يسع المسلمة جهله | C14: =COUNTIFS('الفهرس العام'!$B$2:$B$2508,"دورة ما لا يسع المسلمة جهله",'الفهرس العام'!$C$2:$C$2508,B14)
A15: التزكية | C15: =COUNTIF('الفهرس العام'!$B$2:$B$2508,A15)
B16: سلسلة الطريق إلى البيت العتيق | C16: =COUNTIFS('الفهرس العام'!$B$2:$B$2508,"التزكية",'الفهرس العام'!$C$2:$C$2508,B16)
B17: سلسلة شرح الأسماء الحسنى | C17: =COUNTIFS('الفهرس العام'!$B$2:$B$2508,"التزكية",'الفهرس العام'!$C$2:$C$2508,B17)
B18: شرح طاقة ورد في فقه الورد | C18: =COUNTIFS('الفهرس العام'!$B$2:$B$2508,"التزكية",'الفهرس العام'!$C$2:$C$2508,B18)
B19: سلسلة تأملات إيمانية في أدعية النبي ﷺ | C19: =COUNTIFS('الفهرس العام'!$B$2:$B$2508,"التزكية",'الفهرس العام'!$C$2:$C$2508,B19)
B20: سيرة إبراهيم الخليل عليه السلام | C20: =COUNTIFS('الفهرس العام'!$B$2:$B$2508,"التزكية",'الفهرس العام'!$C$2:$C$2508,B20)
B21: تأملات إيمانية في أدعية الحج والعمرة | C21: =COUNTIFS('الفهرس العام'!$B$2:$B$2508,"التزكية",'الفهرس العام'!$C$2:$C$2508,B21)
B22: شرح رسالة ذوق الصلاة لابن القيم | C22: =COUNTIFS('الفهرس العام'!$B$2:$B$2508,"التزكية",'الفهرس العام'!$C$2:$C$2508,B22)
B23: شرح الداء والدواء لابن القيم | C23: =COUNTIFS('الفهرس العام'!$B$2:$B$2508,"التزكية",'الفهرس العام'!$C$2:$C$2508,B23)
B24: تأملات ورقائق متفرقة | C24: =COUNTIFS('الفهرس العام'!$B$2:$B$2508,"التزكية",'الفهرس العام'!$C$2:$C$2508,B24)
A25: قصص الأنبياء | C25: =COUNTIF('الفهرس العام'!$B$2:$B$2508,A25)
B26: سلسلة تأملات إيمانية في قصص الأنبياء | C26: =COUNTIFS('الفهرس العام'!$B$2:$B$2508,"قصص الأنبياء",'الفهرس العام'!$C$2:$C$2508,B26)
A27: السيرة النبوية | C27: =COUNTIF('الفهرس العام'!$B$2:$B$2508,A27)
B28: لقاءات السيرة النبوية | C28: =COUNTIFS('الفهرس العام'!$B$2:$B$2508,"السيرة النبوية",'الفهرس العام'!$C$2:$C$2508,B28)
A29: الحديث | C29: =COUNTIF('الفهرس العام'!$B$2:$B$2508,A29)
B30: شرح البيقونية في مصطلح الحديث (دورة مصطلح الحديث) | C30: =COUNTIFS('الفهرس العام'!$B$2:$B$2508,"الحديث",'الفهرس العام'!$C$2:$C$2508,B30)
A31: شروح السنة | C31: =COUNTIF('الفهرس العام'!$B$2:$B$2508,A31)
B32: شرح السلسلة الصحيحة (كاملة) | C32: =COUNTIFS('الفهرس العام'!$B$2:$B$2508,"شروح السنة",'الفهرس العام'!$C$2:$C$2508,B32)
B33: شرح رياض الصالحين (متجدد) | C33: =COUNTIFS('الفهرس العام'!$B$2:$B$2508,"شروح السنة",'الفهرس العام'!$C$2:$C$2508,B33)
B34: شرح صحيح الإمام مسلم (متجدد) | C34: =COUNTIFS('الفهرس العام'!$B$2:$B$2508,"شروح السنة",'الفهرس العام'!$C$2:$C$2508,B34)
B35: شرح صحيح البخاري | C35: =COUNTIFS('الفهرس العام'!$B$2:$B$2508,"شروح السنة",'الفهرس العام'!$C$2:$C$2508,B35)
B36: أحاديث وتعليقات | C36: =COUNTIFS('الفهرس العام'!$B$2:$B$2508,"شروح السنة",'الفهرس العام'!$C$2:$C$2508,B36)
A37: العقيدة | C37: =COUNTIF('الفهرس العام'!$B$2:$B$2508,A37)
B38: شرح أصول الإيمان | C38: =COUNTIFS('الفهرس العام'!$B$2:$B$2508,"العقيدة",'الفهرس العام'!$C$2:$C$2508,B38)
B39: شرح العقيدة الواسطية | C39: =COUNTIFS('الفهرس العام'!$B$2:$B$2508,"العقيدة",'الفهرس العام'!$C$2:$C$2508,B39)
B40: شرح لمعة الاعتقاد لابن قدامة | C40: =COUNTIFS('الفهرس العام'!$B$2:$B$2508,"العقيدة",'الفهرس العام'!$C$2:$C$2508,B40)
B41: شرح اعتقاد أهل السنة | C41: =COUNTIFS('الفهرس العام'!$B$2:$B$2508,"العقيدة",'الفهرس العام'!$C$2:$C$2508,B41)
...

Sheet الفهرس العام
A1: م | B1: التصنيف | C1: السلسلة | D1: الكتاب / الباب | E1: رقم الدرس | F1: عنوان الدرس | G1: الموضوعات | H1: النوع | I1: التاريخ | J1: الرابط
A2: 1 | B2: الاقتصاد الإسلامي | C2: شرح مقدمة في الاقتصاد الإسلامي | E2: 1 | F2: مقدمة اقتصاد إسلامي | G2: خصائص الاقتصاد الإسلامي - 1 | H2: صوتي | I2: 2024-11-29 | J2: فتح في تليجرام
A3: 2 | B3: الاقتصاد الإسلامي | C3: شرح مقدمة في الاقتصاد الإسلامي | E3: 2 | F3: مقدمة اقتصاد إسلامي | G3: مباديء الاقتصاد الإسلامي، دوره في علاج الأزمة الاقتصادية | H3: صوتي | I3: 2024-11-29 | J3: فتح في تليجرام
A4: 3 | B4: الاقتصاد الإسلامي | C4: شرح مقدمة في الاقتصاد الإسلامي | F4: شرح مقدمة في الاقتصاد الإسلامي (2024-11-30) | H4: PDF | I4: 2024-11-30 | J4: فتح في تليجرام
A5: 4 | B5: الاقتصاد الإسلامي | C5: شرح كتاب أربعون قاعدة في فقه معاملات الأسواق | F5: شرح كتاب أربعون قاعدة في فقه معاملات الأسواق (2026-07-17) | H5: صوتي | I5: 2026-07-17 | J5: فتح في تليجرام
A6: 5 | B6: الاقتصاد الإسلامي | C6: استشارات اقتصادية | E6: 28 | F6: شرح كتاب البيوع والكسب والزهد-28 | G6: فضل مايؤكل من الزرع والغرس • احكام الرجوع في الهبة • حكم الاحتكار، ضوابط الاحتكار المحرم، جزاء المحتكر | H6: صوتي | I6: 2022-10-29 | J6: فتح في تليجرام
A7: 6 | B7: الاقتصاد الإسلامي | C7: استشارات اقتصادية | E7: 29 | F7: شرح كتاب البيوع والكسب والزهد-29 | G7: الاقالة في البيع • حكم بيع الوفاء • من باع بيعتين فى بيعة فله اوكسهما أو الربا | H7: صوتي | I7: 2022-10-30 | J7: فتح في تليجرام
A8: 7 | B8: الاقتصاد الإسلامي | C8: استشارات اقتصادية | F8: أحكام وفتاوى مهمة: صور التحويل عبر فودافون كاش | G8: صور التحويل عن طريق فودافون كاش واحكامها • حكم سلفني شكرا | H8: صوتي | I8: 2023-08-14 | J8: فتح في تليجرام
A9: 8 | B9: الاقتصاد الإسلامي | C9: استشارات اقتصادية | F9: فتاوي اقتصادية | H9: صوتي | I9: 2023-10-14 | J9: فتح في تليجرام
A10: 9 | B10: الاقتصاد الإسلامي | C10: استشارات اقتصادية | F10: حكم مبادرة جمارك السيارات | H10: صوتي | I10: 2023-12-22 | J10: فتح في تليجرام
A11: 10 | B11: الاقتصاد الإسلامي | C11: استشارات اقتصادية | E11: 3 | F11: 3.المجلس الثالث | H11: صوتي | I11: 2024-01-12 | J11: فتح في تليجرام
A12: 11 | B12: الاقتصاد الإسلامي | C12: استشارات اقتصادية | E12: 4 | F12: 4.المجلس الرابع | H12: صوتي | I12: 2024-01-26 | J12: فتح في تليجرام
A13: 12 | B13: الاقتصاد الإسلامي | C13: استشارات اقتصادية | E13: 5 | F13: 5.المجلس الخامس | H13: صوتي | I13: 2024-01-26 | J13: فتح في تليجرام
A14: 13 | B14: الاقتصاد الإسلامي | C14: استشارات اقتصادية | E14: 6 | F14: 6. المجلس السادس | H14: صوتي | I14: 2024-02-02 | J14: فتح في تليجرام
A15: 14 | B15: الاقتصاد الإسلامي | C15: استشارات اقتصادية | E15: 7 | F15: 7. المجلس السابع | H15: صوتي | I15: 2024-02-02 | J15: فتح في تليجرام
A16: 15 | B16: الاقتصاد الإسلامي | C16: استشارات اقتصادية | E16: 1 | F16: البيوع 1 | H16: صوتي | I16: 2024-05-01 | J16: فتح في تليجرام
A17: 16 | B17: الاقتصاد الإسلامي | C17: استشارات اقتصادية | E17: 3 | F17: البيوع 3 | H17: صوتي | I17: 2024-05-09 | J17: فتح في تليجرام
A18: 17 | B18: الاقتصاد الإسلامي | C18: استشارات اقتصادية | E18: 9 | F18: البيوع 9 | H18: صوتي | I18: 2024-08-28 | J18: فتح في تليجرام
A19: 18 | B19: الاقتصاد الإسلامي | C19: استشارات اقتصادية | F19: أنواع البطاقات الائتمانية | G19: حكم شراء الذهب بالكريدت كارد | H19: صوتي | I19: 2024-08-29 | J19: فتح في تليجرام
A20: 19 | B20: الاقتصاد الإسلامي | C20: استشارات اقتصادية | E20: 5 | F20: البيوع 5 | H20: صوتي | I20: 2024-08-29 | J20: فتح في تليجرام
A21: 20 | B21: الاقتصاد الإسلامي | C21: استشارات اقتصادية | F21: حكم شراء الذهب عن طريق الانستاباي | H21: صوتي | I21: 2024-08-30 | J21: فتح في تليجرام
A22: 21 | B22: الاقتصاد الإسلامي | C22: استشارات اقتصادية | E22: 10 | F22: البيوع 10 | H22: صوتي | I22: 2024-09-12 | J22: فتح في تليجرام
A23: 22 | B23: الاقتصاد الإسلامي | C23: استشارات اقتصادية | E23: 11 | F23: البيوع 11 | H23: صوتي | I23: 2024-09-23 | J23: فتح في تليجرام
A24: 23 | B24: الاقتصاد الإسلامي | C24: استشارات اقتصادية | E24: 12 | F24: البيوع 12 | H24: صوتي | I24: 2024-09-23 | J24: فتح في تليجرام
A25: 24 | B25: الاقتصاد الإسلامي | C25: استشارات اقتصادية | E25: 14 | F25: البيوع 14 | H25: صوتي | I25: 2024-10-17 | J25: فتح في تليجرام
A26: 25 | B26: الاقتصاد الإسلامي | C26: استشارات اقتصادية | F26: فتاوي اقتصادية | G26: حكم شراء أسهم في شركة اصل نشاطها حلال، وتمارس بعض المعاملات الربوية. | H26: صوتي | I26: 2024-11-18 | J26: فتح في تليجرام
A27: 26 | B27: الاقتصاد الإسلامي | C27: استشارات اقتصادية | F27: فتاوي اقتصادية | G27: حساب زكاة الشركات ورواتب العمال. | H27: صوتي | I27: 2024-11-18 | J27: فتح في تليجرام
A28: 27 | B28: الاقتصاد الإسلامي | C28: استشارات اقتصادية | F28: حكم العمل في شركة RGA واخذ اجر على المشاهدات | H28: صوتي | I28: 2025-01-05 | J28: فتح في تليجرام
A29: 28 | B29: الاقتصاد الإسلامي | C29: استشارات اقتصادية | F29: حكم شقق الاسكان الاجتماعي | G29: ولو ربا • ايه وجه الربا ال فيها ؟ | H29: صوتي | I29: 2025-01-06 | J29: فتح في تليجرام
A30: 29 | B30: الاقتصاد الإسلامي | C30: استشارات اقتصادية | F30: فتاوي اقتصادية | H30: صوتي | I30: 2025-01-06 | J30: فتح في تليجرام
A31: 30 | B31: الاقتصاد الإسلامي | C31: استشارات اقتصادية | F31: فتاوي اقتصادية | H31: صوتي | I31: 2025-01-26 | J31: فتح في تليجرام
A32: 31 | B32: الاقتصاد الإسلامي | C32: استشارات اقتصادية | F32: فتاوي اقتصادية | H32: صوتي | I32: 2025-01-26 | J32: فتح في تليجرام
A33: 32 | B33: الاقتصاد الإسلامي | C33: استشارات اقتصادية | F33: حكم البيع والشراء عبر الدروبشوبينج | H33: صوتي | I33: 2025-05-03 | J33: فتح في تليجرام
A34: 33 | B34: الاقتصاد الإسلامي | C34: استشارات اقتصادية | F34: ملخص صور تمويل البنوك للسيارات والعقارات | G34: القرض التقليدي • المرابحة. • الإجارة المنتهية بالتمليك • المشاركة المتناقصة | H34: صوتي | I34: 2025-05-20 | J34: فتح في تليجرام
A35: 34 | B35: الاقتصاد الإسلامي | C35: استشارات اقتصادية | F35: شراء الشقق بالرسوم الهندسية قبل بنائها، المخرج الشرعي | H35: صوتي | I35: 2025-08-27 | J35: فتح في تليجرام
A36: 35 | B36: الاقتصاد الإسلامي | C36: استشارات اقتصادية | F36: بيع المرابحة للآمر بالشراء والمشاركة المتناقصة في تمويل المصارف الإسلامية للسيارات والعقارات | H36: صوتي | I36: 2025-08-27 | J36: فتح في تليجرام
A37: 36 | B37: الاقتصاد الإسلامي | C37: استشارات اقتصادية | F37: تيلدا | H37: صوتي | I37: 2025-09-04 | J37: فتح في تليجرام
A38: 37 | B38: الاقتصاد الإسلامي | C38: استشارات اقتصادية | F38: رياض الجنة (م محمود علي) "قناة علمية - دعوية - فكرية" | G38: حكم بيع الأرقام الوهمية بالعملات الرقمية | H38: صوتي | I38: 2025-09-22 | J38: فتح في تليجرام
A39: 38 | B39: الاقتصاد الإسلامي | C39: استشارات اقتصادية | F39: بيع الأرض المخصصة من قبل الدولة قبل قبضها | H39: صوتي | I39: 2025-10-20 | J39: فتح في تليجرام
A40: 39 | B40: الاقتصاد الإسلامي | C40: استشارات اقتصادية | F40: غرامة التأخير وأثره في العقود | H40: صوتي | I40: 2025-10-20 | J40: فتح في تليجرام
...

Sheet الاقتصاد الإسلامي
A1: م | B1: التصنيف | C1: السلسلة | D1: الكتاب / الباب | E1: رقم الدرس | F1: عنوان الدرس | G1: الموضوعات | H1: النوع | I1: التاريخ | J1: الرابط
A2: 1 | B2: الاقتصاد الإسلامي | C2: شرح مقدمة في الاقتصاد الإسلامي | E2: 1 | F2: مقدمة اقتصاد إسلامي | G2: خصائص الاقتصاد الإسلامي - 1 | H2: صوتي | I2: 2024-11-29 | J2: فتح في تليجرام
A3: 2 | B3: الاقتصاد الإسلامي | C3: شرح مقدمة في الاقتصاد الإسلامي | E3: 2 | F3: مقدمة اقتصاد إسلامي | G3: مباديء الاقتصاد الإسلامي، دوره في علاج الأزمة الاقتصادية | H3: صوتي | I3: 2024-11-29 | J3: فتح في تليجرام
A4: 3 | B4: الاقتصاد الإسلامي | C4: شرح مقدمة في الاقتصاد الإسلامي | F4: شرح مقدمة في الاقتصاد الإسلامي (2024-11-30) | H4: PDF | I4: 2024-11-30 | J4: فتح في تليجرام
A5: 4 | B5: الاقتصاد الإسلامي | C5: شرح كتاب أربعون قاعدة في فقه معاملات الأسواق | F5: شرح كتاب أربعون قاعدة في فقه معاملات الأسواق (2026-07-17) | H5: صوتي | I5: 2026-07-17 | J5: فتح في تليجرام
A6: 5 | B6: الاقتصاد الإسلامي | C6: استشارات اقتصادية | E6: 28 | F6: شرح كتاب البيوع والكسب والزهد-28 | G6: فضل مايؤكل من الزرع والغرس • احكام الرجوع في الهبة • حكم الاحتكار، ضوابط الاحتكار المحرم، جزاء المحتكر | H6: صوتي | I6: 2022-10-29 | J6: فتح في تليجرام
A7: 6 | B7: الاقتصاد الإسلامي | C7: استشارات اقتصادية | E7: 29 | F7: شرح كتاب البيوع والكسب والزهد-29 | G7: الاقالة في البيع • حكم بيع الوفاء • من باع بيعتين فى بيعة فله اوكسهما أو الربا | H7: صوتي | I7: 2022-10-30 | J7: فتح في تليجرام
A8: 7 | B8: الاقتصاد الإسلامي | C8: استشارات اقتصادية | F8: أحكام وفتاوى مهمة: صور التحويل عبر فودافون كاش | G8: صور التحويل عن طريق فودافون كاش واحكامها • حكم سلفني شكرا | H8: صوتي | I8: 2023-08-14 | J8: فتح في تليجرام
A9: 8 | B9: الاقتصاد الإسلامي | C9: استشارات اقتصادية | F9: فتاوي اقتصادية | H9: صوتي | I9: 2023-10-14 | J9: فتح في تليجرام
A10: 9 | B10: الاقتصاد الإسلامي | C10: استشارات اقتصادية | F10: حكم مبادرة جمارك السيارات | H10: صوتي | I10: 2023-12-22 | J10: فتح في تليجرام
A11: 10 | B11: الاقتصاد الإسلامي | C11: استشارات اقتصادية | E11: 3 | F11: 3.المجلس الثالث | H11: صوتي | I11: 2024-01-12 | J11: فتح في تليجرام
A12: 11 | B12: الاقتصاد الإسلامي | C12: استشارات اقتصادية | E12: 4 | F12: 4.المجلس الرابع | H12: صوتي | I12: 2024-01-26 | J12: فتح في تليجرام
A13: 12 | B13: الاقتصاد الإسلامي | C13: استشارات اقتصادية | E13: 5 | F13: 5.المجلس الخامس | H13: صوتي | I13: 2024-01-26 | J13: فتح في تليجرام
A14: 13 | B14: الاقتصاد الإسلامي | C14: استشارات اقتصادية | E14: 6 | F14: 6. المجلس السادس | H14: صوتي | I14: 2024-02-02 | J14: فتح في تليجرام
A15: 14 | B15: الاقتصاد الإسلامي | C15: استشارات اقتصادية | E15: 7 | F15: 7. المجلس السابع | H15: صوتي | I15: 2024-02-02 | J15: فتح في تليجرام
A16: 15 | B16: الاقتصاد الإسلامي | C16: استشارات اقتصادية | E16: 1 | F16: البيوع 1 | H16: صوتي | I16: 2024-05-01 | J16: فتح في تليجرام
A17: 16 | B17: الاقتصاد الإسلامي | C17: استشارات اقتصادية | E17: 3 | F17: البيوع 3 | H17: صوتي | I17: 2024-05-09 | J17: فتح في تليجرام
A18: 17 | B18: الاقتصاد الإسلامي | C18: استشارات اقتصادية | E18: 9 | F18: البيوع 9 | H18: صوتي | I18: 2024-08-28 | J18: فتح في تليجرام
A19: 18 | B19: الاقتصاد الإسلامي | C19: استشارات اقتصادية | F19: أنواع البطاقات الائتمانية | G19: حكم شراء الذهب بالكريدت كارد | H19: صوتي | I19: 2024-08-29 | J19: فتح في تليجرام
A20: 19 | B20: الاقتصاد الإسلامي | C20: استشارات اقتصادية | E20: 5 | F20: البيوع 5 | H20: صوتي | I20: 2024-08-29 | J20: فتح في تليجرام
A21: 20 | B21: الاقتصاد الإسلامي | C21: استشارات اقتصادية | F21: حكم شراء الذهب عن طريق الانستاباي | H21: صوتي | I21: 2024-08-30 | J21: فتح في تليجرام
A22: 21 | B22: الاقتصاد الإسلامي | C22: استشارات اقتصادية | E22: 10 | F22: البيوع 10 | H22: صوتي | I22: 2024-09-12 | J22: فتح في تليجرام
A23: 22 | B23: الاقتصاد الإسلامي | C23: استشارات اقتصادية | E23: 11 | F23: البيوع 11 | H23: صوتي | I23: 2024-09-23 | J23: فتح في تليجرام
A24: 23 | B24: الاقتصاد الإسلامي | C24: استشارات اقتصادية | E24: 12 | F24: البيوع 12 | H24: صوتي | I24: 2024-09-23 | J24: فتح في تليجرام
A25: 24 | B25: الاقتصاد الإسلامي | C25: استشارات اقتصادية | E25: 14 | F25: البيوع 14 | H25: صوتي | I25: 2024-10-17 | J25: فتح في تليجرام
A26: 25 | B26: الاقتصاد الإسلامي | C26: استشارات اقتصادية | F26: فتاوي اقتصادية | G26: حكم شراء أسهم في شركة اصل نشاطها حلال، وتمارس بعض المعاملات الربوية. | H26: صوتي | I26: 2024-11-18 | J26: فتح في تليجرام
A27: 26 | B27: الاقتصاد الإسلامي | C27: استشارات اقتصادية | F27: فتاوي اقتصادية | G27: حساب زكاة الشركات ورواتب العمال. | H27: صوتي | I27: 2024-11-18 | J27: فتح في تليجرام
A28: 27 | B28: الاقتصاد الإسلامي | C28: استشارات اقتصادية | F28: حكم العمل في شركة RGA واخذ اجر على المشاهدات | H28: صوتي | I28: 2025-01-05 | J28: فتح في تليجرام
A29: 28 | B29: الاقتصاد الإسلامي | C29: استشارات اقتصادية | F29: حكم شقق الاسكان الاجتماعي | G29: ولو ربا • ايه وجه الربا ال فيها ؟ | H29: صوتي | I29: 2025-01-06 | J29: فتح في تليجرام
A30: 29 | B30: الاقتصاد الإسلامي | C30: استشارات اقتصادية | F30: فتاوي اقتصادية | H30: صوتي | I30: 2025-01-06 | J30: فتح في تليجرام
A31: 30 | B31: الاقتصاد الإسلامي | C31: استشارات اقتصادية | F31: فتاوي اقتصادية | H31: صوتي | I31: 2025-01-26 | J31: فتح في تليجرام
A32: 31 | B32: الاقتصاد الإسلامي | C32: استشارات اقتصادية | F32: فتاوي اقتصادية | H32: صوتي | I32: 2025-01-26 | J32: فتح في تليجرام
A33: 32 | B33: الاقتصاد الإسلامي | C33: استشارات اقتصادية | F33: حكم البيع والشراء عبر الدروبشوبينج | H33: صوتي | I33: 2025-05-03 | J33: فتح في تليجرام
A34: 33 | B34: الاقتصاد الإسلامي | C34: استشارات اقتصادية | F34: ملخص صور تمويل البنوك للسيارات والعقارات | G34: القرض التقليدي • المرابحة. • الإجارة المنتهية بالتمليك • المشاركة المتناقصة | H34: صوتي | I34: 2025-05-20 | J34: فتح في تليجرام
A35: 34 | B35: الاقتصاد الإسلامي | C35: استشارات اقتصادية | F35: شراء الشقق بالرسوم الهندسية قبل بنائها، المخرج الشرعي | H35: صوتي | I35: 2025-08-27 | J35: فتح في تليجرام
A36: 35 | B36: الاقتصاد الإسلامي | C36: استشارات اقتصادية | F36: بيع المرابحة للآمر بالشراء والمشاركة المتناقصة في تمويل المصارف الإسلامية للسيارات والعقارات | H36: صوتي | I36: 2025-08-27 | J36: فتح في تليجرام
A37: 36 | B37: الاقتصاد الإسلامي | C37: استشارات اقتصادية | F37: تيلدا | H37: صوتي | I37: 2025-09-04 | J37: فتح في تليجرام
A38: 37 | B38: الاقتصاد الإسلامي | C38: استشارات اقتصادية | F38: رياض الجنة (م محمود علي) "قناة علمية - دعوية - فكرية" | G38: حكم بيع الأرقام الوهمية بالعملات الرقمية | H38: صوتي | I38: 2025-09-22 | J38: فتح في تليجرام
A39: 38 | B39: الاقتصاد الإسلامي | C39: استشارات اقتصادية | F39: بيع الأرض المخصصة من قبل الدولة قبل قبضها | H39: صوتي | I39: 2025-10-20 | J39: فتح في تليجرام
A40: 39 | B40: الاقتصاد الإسلامي | C40: استشارات اقتصادية | F40: غرامة التأخير وأثره في العقود | H40: صوتي | I40: 2025-10-20 | J40: فتح في تليجرام
...

Sheet دورة ما لا يسع المسلمة جهله
A1: م | B1: التصنيف | C1: السلسلة | D1: الكتاب / الباب | E1: رقم الدرس | F1: عنوان الدرس | G1: الموضوعات | H1: النوع | I1: التاريخ | J1: الرابط
A2: 1 | B2: دورة ما لا يسع المسلمة جهله | C2: دورة ما لا يسع المسلمة جهله | E2: 1 | F2: الدورة العلمية الصيفية "ما لا يسع المسلمة جهله" | G2: درس 1 عقيدة شرح أصول الإيمان. | H2: صوتي | I2: 2022-06-22 | J2: فتح في تليجرام
A3: 2 | B3: دورة ما لا يسع المسلمة جهله | C3: دورة ما لا يسع المسلمة جهله | E3: 1 | F3: الدورة العلمية الصيفية "ما لا يسع المسلمة جهله" | G3: درس 1 فقه شرح فقه الطهارة - 1 أ | H3: صوتي | I3: 2022-06-22 | J3: فتح في تليجرام
A4: 3 | B4: دورة ما لا يسع المسلمة جهله | C4: دورة ما لا يسع المسلمة جهله | E4: 1 | F4: الدورة العلمية الصيفية "ما لا يسع المسلمة جهله" | G4: درس 1 فقه شرح فقه الطهارة - 1 ب | H4: صوتي | I4: 2022-06-22 | J4: فتح في تليجرام
A5: 4 | B5: دورة ما لا يسع المسلمة جهله | C5: دورة ما لا يسع المسلمة جهله | E5: 2 | F5: الدورة العلمية الصيفية "ما لا يسع المسلمة جهله" | G5: درس 2 عقيدة شرح أصول الإيمان. | H5: صوتي | I5: 2022-06-28 | J5: فتح في تليجرام
A6: 5 | B6: دورة ما لا يسع المسلمة جهله | C6: دورة ما لا يسع المسلمة جهله | E6: 2 | F6: الدورة العلمية الصيفية "ما لا يسع المسلمة جهله" | G6: درس 2 فقه شرح فقه الطهارة | H6: صوتي | I6: 2022-06-28 | J6: فتح في تليجرام
A7: 6 | B7: دورة ما لا يسع المسلمة جهله | C7: دورة ما لا يسع المسلمة جهله | E7: 3 | F7: الدورة العلمية الصيفية "ما لا يسع المسلمة جهله" | G7: درس 3 مراجعة فقه الطهارة وحل الأسئلة. | H7: صوتي | I7: 2022-07-01 | J7: فتح في تليجرام
A8: 7 | B8: دورة ما لا يسع المسلمة جهله | C8: دورة ما لا يسع المسلمة جهله | E8: 3 | F8: الدورة العلمية الصيفية "ما لا يسع المسلمة جهله" | G8: درس 3 شرح اصول الإيمان (توحيد الأسماء والصفات). | H8: صوتي | I8: 2022-07-01 | J8: فتح في تليجرام
A9: 8 | B9: دورة ما لا يسع المسلمة جهله | C9: دورة ما لا يسع المسلمة جهله | E9: 4 | F9: الدورة العلمية الصيفية "ما لا يسع المسلمة جهله" | G9: شرح أصول الإيمان - 4 (الولاء والبراء) | H9: صوتي | I9: 2022-07-01 | J9: فتح في تليجرام
A10: 9 | B10: دورة ما لا يسع المسلمة جهله | C10: دورة ما لا يسع المسلمة جهله | F10: مراجعة أصول الإيمان المستوى الأول-ما لا يسع المسلمة جهله | H10: صوتي | I10: 2022-07-22 | J10: فتح في تليجرام
A11: 10 | B11: دورة ما لا يسع المسلمة جهله | C11: دورة ما لا يسع المسلمة جهله | E11: 5 | F11: المستوى الثاني - شرح أصول الإيمان - 5 (الحكم بما انزل الله) | H11: صوتي | I11: 2022-07-29 | J11: فتح في تليجرام
A12: 11 | B12: دورة ما لا يسع المسلمة جهله | C12: دورة ما لا يسع المسلمة جهله | E12: 1 | F12: المستوى الثاني - شرح مختصر فقه الصلاة - 1 | H12: صوتي | I12: 2022-07-30 | J12: فتح في تليجرام
A13: 12 | B13: دورة ما لا يسع المسلمة جهله | C13: دورة ما لا يسع المسلمة جهله | E13: 6 | F13: المستوى الثاني - شرح أصول الإيمان - 6 (الايمان بالملائكة-الايمان بالكتب) | H13: صوتي | I13: 2022-07-30 | J13: فتح في تليجرام
A14: 13 | B14: دورة ما لا يسع المسلمة جهله | C14: دورة ما لا يسع المسلمة جهله | E14: 2 | F14: المستوى الثاني - شرح مختصر فقه الصلاة - 2 | H14: صوتي | I14: 2022-08-02 | J14: فتح في تليجرام
A15: 14 | B15: دورة ما لا يسع المسلمة جهله | C15: دورة ما لا يسع المسلمة جهله | E15: 7 | F15: المستوى الثاني - شرح أصول الإيمان - 7 (الايمان بالرسل-الايمان باليوم الآخر ) | H15: صوتي | I15: 2022-08-02 | J15: فتح في تليجرام
A16: 15 | B16: دورة ما لا يسع المسلمة جهله | C16: دورة ما لا يسع المسلمة جهله | E16: 3 | F16: المستوى الثاني - شرح مختصر فقه الصلاة - 3 | H16: صوتي | I16: 2022-08-05 | J16: فتح في تليجرام
A17: 16 | B17: دورة ما لا يسع المسلمة جهله | C17: دورة ما لا يسع المسلمة جهله | E17: 8 | F17: المستوى الثاني - شرح أصول الإيمان - 8 (القضاء والقدر مسائل الايمان والكفر - العقيدة في الصحابة) | H17: صوتي | I17: 2022-08-05 | J17: فتح في تليجرام
A18: 17 | B18: دورة ما لا يسع المسلمة جهله | C18: دورة ما لا يسع المسلمة جهله | F18: مراجعة أصول الإيمان المستوى الثاني كاملا | H18: صوتي | I18: 2022-08-16 | J18: فتح في تليجرام
A19: 18 | B19: دورة ما لا يسع المسلمة جهله | C19: دورة ما لا يسع المسلمة جهله | F19: حل اختبار العقيدة المستوى الثاني - ما لا يسع المسلمة جهله | H19: صوتي | I19: 2022-08-22 | J19: فتح في تليجرام
A20: 19 | B20: دورة ما لا يسع المسلمة جهله | C20: دورة ما لا يسع المسلمة جهله | F20: مراجعة فقه الصلاة والطهارة المستوى الثاني - ما لا يسع المسلمة جهله | H20: صوتي | I20: 2022-08-22 | J20: فتح في تليجرام
A21: 20 | B21: دورة ما لا يسع المسلمة جهله | C21: دورة ما لا يسع المسلمة جهله | F21: مذاكرة ما لا يسع المسلمة جهله pdf | H21: PDF | I21: 2024-10-15 | J21: فتح في تليجرام
A22: 21 | B22: دورة ما لا يسع المسلمة جهله | C22: دورة ما لا يسع المسلمة جهله | F22: الافتتاحي | G22: مقدمة في طلب العلم الواجب | H22: صوتي | I22: 2026-04-07 | J22: فتح في تليجرام
A23: 22 | B23: دورة ما لا يسع المسلمة جهله | C23: دورة ما لا يسع المسلمة جهله | F23: أسئلة اللقاء الافتتاحي | H23: صوتي | I23: 2026-04-07 | J23: فتح في تليجرام
A24: 23 | B24: دورة ما لا يسع المسلمة جهله | C24: دورة ما لا يسع المسلمة جهله | F24: أجوبة أسئلة المستوى الأول | H24: صوتي | I24: 2026-06-16 | J24: فتح في تليجرام
A25: 24 | B25: دورة ما لا يسع المسلمة جهله | C25: دورة ما لا يسع المسلمة جهله | F25: لقاء المحرم... أجوبة الأسئلة للمستوى الاول | H25: صوتي | I25: 2026-07-05 | J25: فتح في تليجرام
A26: 25 | B26: دورة ما لا يسع المسلمة جهله | C26: دورة ما لا يسع المسلمة جهله | F26: استشارات النساء | G26: (ما لا يسع المسلمة جهله) | H26: صوتي | I26: 2026-07-06 | J26: فتح في تليجرام

Sheet التزكية
A1: م | B1: التصنيف | C1: السلسلة | D1: الكتاب / الباب | E1: رقم الدرس | F1: عنوان الدرس | G1: الموضوعات | H1: النوع | I1: التاريخ | J1: الرابط
A2: 1 | B2: التزكية | C2: سلسلة الطريق إلى البيت العتيق | D2: شرح حديث جابر في صفة حجة النبي ﷺ | E2: 1 | F2: رضي الله عنه في صفة حجة النبي صلى الله عليه وسلم - 1 | H2: صوتي | I2: 2022-07-08 | J2: فتح في تليجرام
A3: 2 | B3: التزكية | C3: سلسلة الطريق إلى البيت العتيق | D3: شرح حديث جابر في صفة حجة النبي ﷺ | E3: 2 | F3: رضي الله عنه في صفة حجة النبي صلى الله عليه وسلم - 2 | G3: أعمال يوم النحر (العيد) | H3: صوتي | I3: 2022-07-09 | J3: فتح في تليجرام
A4: 3 | B4: التزكية | C4: سلسلة الطريق إلى البيت العتيق | D4: شرح حديث جابر في صفة حجة النبي ﷺ | E4: 3 | F4: رضي الله عنه في صفة حجة النبي صلى الله عليه وسلم - 3 | G4: تتمة أعمال الحج في أيام التشريق | H4: صوتي | I4: 2022-07-11 | J4: فتح في تليجرام
A5: 4 | B5: التزكية | C5: سلسلة الطريق إلى البيت العتيق | D5: شرح حديث جابر في صفة حجة النبي ﷺ | E5: 4 | F5: رضي الله عنه في صفة حجة النبي صلى الله عليه وسلم - 4 | G5: تتمة أعمال الحج طواف الوداع والزيارة | H5: صوتي | I5: 2022-07-12 | J5: فتح في تليجرام
A6: 5 | B6: التزكية | C6: سلسلة الطريق إلى البيت العتيق | D6: شرح حديث جابر في صفة حجة النبي ﷺ | E6: 4 | F6: (حديث جابر-بداية رحلة الحج) | H6: صوتي | I6: 2024-04-28 | J6: فتح في تليجرام
A7: 6 | B7: التزكية | C7: سلسلة الطريق إلى البيت العتيق | D7: شرح حديث جابر في صفة حجة النبي ﷺ | E7: 5 | F7: (حديث جابر-2 ذو الحليفة الوادي المبارك) | H7: صوتي | I7: 2024-04-29 | J7: فتح في تليجرام
A8: 7 | B8: التزكية | C8: سلسلة الطريق إلى البيت العتيق | D8: شرح حديث جابر في صفة حجة النبي ﷺ | E8: 6 | F8: (حديث جابر-3 احرام النفساء والحائض- تأملات إيمانية في التلبية-1) | H8: صوتي | I8: 2024-04-30 | J8: فتح في تليجرام
A9: 8 | B9: التزكية | C9: سلسلة الطريق إلى البيت العتيق | D9: شرح حديث جابر في صفة حجة النبي ﷺ | E9: 7 | F9: (حديث جابر-4 - تأملات إيمانية في التلبية-2) | H9: صوتي | I9: 2024-05-01 | J9: فتح في تليجرام
A10: 9 | B10: التزكية | C10: سلسلة الطريق إلى البيت العتيق | D10: شرح حديث جابر في صفة حجة النبي ﷺ | E10: 8 | F10: (حديث جابر-5 - الطريق إلى البيت ووصول البيت الحرام) | H10: صوتي | I10: 2024-05-02 | J10: فتح في تليجرام
A11: 10 | B11: التزكية | C11: سلسلة الطريق إلى البيت العتيق | D11: شرح حديث جابر في صفة حجة النبي ﷺ | E11: 9 | F11: (حديث جابر-6- الطواف- تأملات إيمانية في دعاء الطواف) | H11: صوتي | I11: 2024-05-03 | J11: فتح في تليجرام
A12: 11 | B12: التزكية | C12: سلسلة الطريق إلى البيت العتيق | D12: شرح حديث جابر في صفة حجة النبي ﷺ | E12: 10 | F12: (حديث جابر-7- الطواف- تأملات إيمانية في ركعتي الطواف- سورة الكافرون ) | H12: صوتي | I12: 2024-05-04 | J12: فتح في تليجرام
A13: 12 | B13: التزكية | C13: سلسلة الطريق إلى البيت العتيق | D13: شرح حديث جابر في صفة حجة النبي ﷺ | E13: 11 | F13: (حديث جابر-8- الطواف- تأملات إيمانية في ركعتي الطواف- سورة الإخلاص ) | H13: صوتي | I13: 2024-05-07 | J13: فتح في تليجرام
A14: 13 | B14: التزكية | C14: سلسلة الطريق إلى البيت العتيق | D14: شرح حديث جابر في صفة حجة النبي ﷺ | E14: 12 | F14: (حديث جابر-9- تأملات إيمانية في الدعاء علي الصفا) | H14: صوتي | I14: 2024-05-07 | J14: فتح في تليجرام
A15: 14 | B15: التزكية | C15: سلسلة الطريق إلى البيت العتيق | D15: شرح حديث جابر في صفة حجة النبي ﷺ | E15: 13 | F15: (حديث جابر-10- تأملات إيمانية في السعي وقصة بناء البيت-1) | H15: صوتي | I15: 2024-05-07 | J15: فتح في تليجرام
A16: 15 | B16: التزكية | C16: سلسلة الطريق إلى البيت العتيق | D16: شرح حديث جابر في صفة حجة النبي ﷺ | E16: 14 | F16: (حديث جابر-11- تأملات إيمانية في السعي وقصة بناء البيت-2) | H16: صوتي | I16: 2024-05-08 | J16: فتح في تليجرام
A17: 16 | B17: التزكية | C17: سلسلة الطريق إلى البيت العتيق | D17: شرح حديث جابر في صفة حجة النبي ﷺ | E17: 15 | F17: (حديث جابر-12- التحلل من العمرة المتمتع-الإحرام بالحج يوم التروية) | H17: صوتي | I17: 2024-05-09 | J17: فتح في تليجرام
... A27: 26 | B27: التزكية | C27: سلسلة الطريق إلى البيت العتيق | D27: شرح حديث جابر في صفة حجة النبي ﷺ | E27: 1 | F27: حديث جابر في الحج-1 | H27: صوتي | I27: 2026-05-25 | J27: فتح في تليجرام
A28: 27 | B28: التزكية | C28: سلسلة الطريق إلى البيت العتيق | D28: شرح حديث جابر في صفة حجة النبي ﷺ | E28: 2 | F28: حديث جابر في الحج-2 | G28: يوم التروية | H28: صوتي | I28: 2026-05-26 | J28: فتح في تليجرام
A29: 28 | B29: التزكية | C29: سلسلة الطريق إلى البيت العتيق | D29: شرح حديث جابر في صفة حجة النبي ﷺ | E29: 3 | F29: حديث جابر في الحج-3 | G29: أعمال يوم عرفة.. وفضائله | H29: صوتي | I29: 2026-05-26 | J29: فتح في تليجرام
A30: 29 | B30: التزكية | C30: سلسلة الطريق إلى البيت العتيق | D30: شرح حديث جابر في صفة حجة النبي ﷺ | E30: 4 | F30: حديث جابر في الحج-4 | G30: أعمال يوم النحر.. وتتمة أعمال الحج | H30: صوتي | I30: 2026-05-30 | J30: فتح في تليجرام
A31: 30 | B31: التزكية | C31: سلسلة الطريق إلى البيت العتيق | E31: 1 | F31: سلسلة الطريق إلى البيت العتيق - الدرس 1 | H31: صوتي | I31: 2024-04-15 | J31: فتح في تليجرام
A32: 31 | B32: التزكية | C32: سلسلة الطريق إلى البيت العتيق | E32: 2 | F32: (تأملات إيمانية في دعاء السفر) | H32: صوتي | I32: 2024-04-16 | J32: فتح في تليجرام
A33: 32 | B33: التزكية | C33: سلسلة الطريق إلى البيت العتيق | E33: 3 | F33: (تأملات إيمانية في دعاء السفر-2) | H33: صوتي | I33: 2024-04-17 | J33: فتح في تليجرام
A34: 33 | B34: التزكية | C34: سلسلة الطريق إلى البيت العتيق | E34: 25 | F34: (رمي الجمار والمبيت بمنى) | H34: صوتي | I34: 2024-05-29 | J34: فتح في تليجرام
A35: 34 | B35: التزكية | C35: سلسلة الطريق إلى البيت العتيق | E35: 26 | F35: (رمي الجمار والمبيت بمنى - سنة التحصيب) | H35: صوتي | I35: 2024-06-04 | J35: فتح في تليجرام
A36: 35 | B36: التزكية | C36: سلسلة الطريق إلى البيت العتيق | E36: 27 | F36: (طواف الوداع - دعاء العودة من الحج-ولكن يناله التقوى منكم) | H36: صوتي | I36: 2024-06-04 | J36: فتح في تليجرام
A37: 36 | B37: التزكية | C37: سلسلة الطريق إلى البيت العتيق | E37: 1 | F37: جديد في رحاب البيت العتيق 1 | H37: صوتي | I37: 2025-09-04 | J37: فتح في تليجرام
A38: 37 | B38: التزكية | C38: سلسلة الطريق إلى البيت العتيق | E38: 2 | F38: جديد في رحاب البيت العتيق 2 | H38: صوتي | I38: 2025-09-04 | J38: فتح في تليجرام
A39: 38 | B39: التزكية | C39: سلسلة شرح الأسماء الحسنى | E39: 1 | F39: من كتابي (شرح ابن القيم)، شرح المعارج -1 | G39: (اسم الإله) | H39: صوتي | I39: 2022-04-12 | J39: فتح في تليجرام
A40: 39 | B40: التزكية | C40: سلسلة شرح الأسماء الحسنى | E40: 2 | F40: من كتابي (شرح ابن القيم)، شرح المعارج.2 | H40: صوتي | I40: 2022-04-12 | J40: فتح في تليجرام
A41: 40 | B41: التزكية | C41: سلسلة شرح الأسماء الحسنى | F41: شرح الأسماء الحسنى من معارج القبول | H41: PDF | I41: 2022-04-24 | J41: فتح في تليجرام
A42: 41 | B42: التزكية | C42: سلسلة شرح الأسماء الحسنى | D42: عالم الغيب والشهادة | E42: 3 | F42: من كتابي (شرح ابن القيم)، شرح ش المعارج لحافظ حكمي. -3 | G42: اسم الله "عالم الغيب والشهادة"-الخبير. | H42: صوتي | I42: 2022-04-13 | J42: فتح في تليجرام
A43: 42 | B43: التزكية | C43: سلسلة شرح الأسماء الحسنى | D43: رحمن الدنيا والآخرة ورحيمهما | E43: 4 | F43: من كتابي (شرح ابن القيم)، شرح المعارج لحافظ حكمي. -4 | G43: اسم الله "رحمن الدنيا والآخرة ورحيمهما" . | H43: صوتي | I43: 2022-04-14 | J43: فتح في تليجرام
A44: 43 | B44: التزكية | C44: سلسلة شرح الأسماء الحسنى | D44: رحمن الدنيا والآخرة ورحيمهما | E44: 5 | F44: من كتابي (شرح ابن القيم)، شرح المعارج لحافظ حكمي. -5 | G44: تابع اسم الله "رحمن الدنيا والآخرة ورحيمهما" . | H44: صوتي | I44: 2022-04-15 | J44: فتح في تليجرام
A45: 44 | B45: التزكية | C45: سلسلة شرح الأسماء الحسنى | D45: المَلِك، المَالِك | E45: 6 | F45: من كتابي (شرح ابن القيم)، شرح المعارج لحافظ حكمي. -6 | G45: اسم الله "المَلِك، المَالِك" . | H45: صوتي | I45: 2022-04-16 | J45: فتح في تليجرام
A46: 45 | B46: التزكية | C46: سلسلة شرح الأسماء الحسنى | D46: المَلِك، المَالِك | E46: 7 | F46: من كتابي (شرح ابن القيم)، شرح المعارج لحافظ حكمي. -7 | G46: اسم الله "المَلِك، المَالِك" . | H46: صوتي | I46: 2022-04-17 | J46: فتح في تليجرام
A47: 46 | B47: التزكية | C47: سلسلة شرح الأسماء الحسنى | D47: السلام، القدوس | E47: 78 | F47: من كتابي (شرح ابن القيم)، شرح المعارج لحافظ حكمي. -78 | G47: اسم الله "السلام، القدوس " . | H47: صوتي | I47: 2022-04-19 | J47: فتح في تليجرام
A48: 47 | B48: التزكية | C48: سلسلة شرح الأسماء الحسنى | D48: القدوس | E48: 10 | F48: من كتابي (شرح ابن القيم)، شرح المعارج لحافظ حكمي. -10 | G48: تابع اسم الله القدوس " . | H48: صوتي | I48: 2022-04-21 | J48: فتح في تليجرام
A49: 48 | B49: التزكية | C49: سلسلة شرح الأسماء الحسنى | D49: المؤمن | E49: 11 | F49: من كتابي (شرح ابن القيم)، شرح المعارج لحافظ حكمي. -11 | G49: اسم الله المؤمن . | H49: صوتي | I49: 2022-04-22 | J49: فتح في تليجرام
...

Sheet قصص الأنبياء
A1: م | B1: التصنيف | C1: السلسلة | D1: الكتاب / الباب | E1: رقم الدرس | F1: عنوان الدرس | G1: الموضوعات | H1: النوع | I1: التاريخ | J1: الرابط
A2: 1 | B2: قصص الأنبياء | C2: سلسلة تأملات إيمانية في قصص الأنبياء | D2: هود | F2: آيات في هلاك قوم عاد | H2: صوتي | I2: 2022-04-19 | J2: فتح في تليجرام
A3: 2 | B3: قصص الأنبياء | C3: سلسلة تأملات إيمانية في قصص الأنبياء | D3: يونس | E3: 1 | F3: تأملات إيمانية في قصة نبي الله يونس عليه السلام - 1 | H3: صوتي | I3: 2023-03-24 | J3: فتح في تليجرام
A4: 3 | B4: قصص الأنبياء | C4: سلسلة تأملات إيمانية في قصص الأنبياء | D4: يونس | F4: تأملات إيمانية في قصة نبي الله يونس عليه السلام 2 | H4: صوتي | I4: 2023-03-25 | J4: فتح في تليجرام
A5: 4 | B5: قصص الأنبياء | C5: سلسلة تأملات إيمانية في قصص الأنبياء | D5: يونس | F5: تأملات إيمانية في قصة نبي الله يونس عليه السلام 3 | H5: صوتي | I5: 2023-04-03 | J5: فتح في تليجرام
A6: 5 | B6: قصص الأنبياء | C6: سلسلة تأملات إيمانية في قصص الأنبياء | D6: يونس | E6: 4 | F6: يونس - الدرس 4 | H6: صوتي | I6: 2023-04-05 | J6: فتح في تليجرام
A7: 6 | B7: قصص الأنبياء | C7: سلسلة تأملات إيمانية في قصص الأنبياء | D7: سليمان | E7: 1 | F7: نبي الله سليمان عليه السلام - 1 | H7: صوتي | I7: 2023-04-05 | J7: فتح في تليجرام
A8: 7 | B8: قصص الأنبياء | C8: سلسلة تأملات إيمانية في قصص الأنبياء | D8: سليمان | E8: 2 | F8: نبي الله سليمان عليه السلام - 2 | H8: صوتي | I8: 2023-04-07 | J8: فتح في تليجرام
A9: 8 | B9: قصص الأنبياء | C9: سلسلة تأملات إيمانية في قصص الأنبياء | D9: سليمان | E9: 3 | F9: نبي الله سليمان عليه السلام - 3 | H9: صوتي | I9: 2023-04-07 | J9: فتح في تليجرام
A10: 9 | B10: قصص الأنبياء | C10: سلسلة تأملات إيمانية في قصص الأنبياء | D10: سليمان | E10: 4 | F10: نبي الله سليمان عليه السلام - 4 | H10: صوتي | I10: 2023-04-09 | J10: فتح في تليجرام
A11: 10 | B11: قصص الأنبياء | C11: سلسلة تأملات إيمانية في قصص الأنبياء | D11: سليمان | E11: 5 | F11: نبي الله سليمان عليه السلام - 5 | H11: صوتي | I11: 2023-04-09 | J11: فتح في تليجرام
A12: 11 | B12: قصص الأنبياء | C12: سلسلة تأملات إيمانية في قصص الأنبياء | D12: سليمان | E12: 6 | F12: نبي الله سليمان عليه السلام - 6 | H12: صوتي | I12: 2023-04-10 | J12: فتح في تليجرام
A13: 12 | B13: قصص الأنبياء | C13: سلسلة تأملات إيمانية في قصص الأنبياء | D13: داوود | E13: 1 | F13: إيمانية في قصة نبي الله داوود عليه السلام - 1 | H13: صوتي | I13: 2024-03-18 | J13: فتح في تليجرام
A14: 13 | B14: قصص الأنبياء | C14: سلسلة تأملات إيمانية في قصص الأنبياء | D14: داوود | E14: 2 | F14: إيمانية في قصة نبي الله داوود عليه السلام - 2 | H14: صوتي | I14: 2024-03-19 | J14: فتح في تليجرام
A15: 14 | B15: قصص الأنبياء | C15: سلسلة تأملات إيمانية في قصص الأنبياء | D15: داوود | E15: 3 | F15: إيمانية في قصة نبي الله داوود عليه السلام - 3 | H15: صوتي | I15: 2024-03-20 | J15: فتح في تليجرام
A16: 15 | B16: قصص الأنبياء | C16: سلسلة تأملات إيمانية في قصص الأنبياء | D16: يوشع بن نون | E16: 1 | F16: إيمانية في قصة نبي الله يوشع بن نون عليه السلام-1 | H16: صوتي | I16: 2025-03-15 | J16: فتح في تليجرام
A17: 16 | B17: قصص الأنبياء | C17: سلسلة تأملات إيمانية في قصص الأنبياء | D17: يوشع بن نون | E17: 2 | F17: إيمانية في قصة نبي الله يوشع بن نون عليه السلام-2 | H17: صوتي | I17: 2025-03-16 | J17: فتح في تليجرام
... A19: 18 | B19: قصص الأنبياء | C19: سلسلة تأملات إيمانية في قصص الأنبياء | D19: يوشع بن نون | E19: 4 | F19: إيمانية في قصة نبي الله يوشع بن نون عليه السلام-4 | H19: صوتي | I19: 2025-03-20 | J19: فتح في تليجرام
A20: 19 | B20: قصص الأنبياء | C20: سلسلة تأملات إيمانية في قصص الأنبياء | D20: يوشع بن نون | E20: 5 | F20: إيمانية في قصة نبي الله يوشع بن نون عليه السلام-5 | G20: (ختام السلسلة) | H20: صوتي | I20: 2025-03-20 | J20: فتح في تليجرام
A21: 20 | B21: قصص الأنبياء | C21: سلسلة تأملات إيمانية في قصص الأنبياء | D21: مؤمن آل فرعون | E21: 1 | F21: تأملات إيمانية في قصة مؤمن آل فرعون - 1 | H21: صوتي | I21: 2026-03-05 | J21: فتح في تليجرام
A22: 21 | B22: قصص الأنبياء | C22: سلسلة تأملات إيمانية في قصص الأنبياء | D22: مؤمن آل فرعون | E22: 2 | F22: تأملات إيمانية في قصة مؤمن آل فرعون - 2 | H22: صوتي | I22: 2026-03-05 | J22: فتح في تليجرام
A23: 22 | B23: قصص الأنبياء | C23: سلسلة تأملات إيمانية في قصص الأنبياء | D23: مؤمن آل فرعون | E23: 3 | F23: تأملات إيمانية في قصة مؤمن آل فرعون - 3 | H23: صوتي | I23: 2026-03-05 | J23: فتح في تليجرام
A24: 23 | B24: قصص الأنبياء | C24: سلسلة تأملات إيمانية في قصص الأنبياء | D24: مؤمن آل فرعون | E24: 4 | F24: تأملات إيمانية في قصة مؤمن آل فرعون - 4 | H24: صوتي | I24: 2026-03-06 | J24: فتح في تليجرام
A25: 24 | B25: قصص الأنبياء | C25: سلسلة تأملات إيمانية في قصص الأنبياء | D25: مؤمن آل فرعون | E25: 5 | F25: تأملات إيمانية في قصة مؤمن آل فرعون - 5 | H25: صوتي | I25: 2026-03-07 | J25: فتح في تليجرام
A26: 25 | B26: قصص الأنبياء | C26: سلسلة تأملات إيمانية في قصص الأنبياء | D26: مؤمن آل فرعون | E26: 6 | F26: تأملات إيمانية في قصة مؤمن آل فرعون - 6 | H26: صوتي | I26: 2026-03-08 | J26: فتح في تليجرام
A27: 26 | B27: قصص الأنبياء | C27: سلسلة تأملات إيمانية في قصص الأنبياء | D27: مؤمن آل فرعون | E27: 7 | F27: تأملات إيمانية في قصة مؤمن آل فرعون - 7 (الأخيرة) | H27: صوتي | I27: 2026-03-09 | J27: فتح في تليجرام

Sheet السيرة النبوية
A1: م | B1: التصنيف | C1: السلسلة | D1: الكتاب / الباب | E1: رقم الدرس | F1: عنوان الدرس | G1: الموضوعات | H1: النوع | I1: التاريخ | J1: الرابط
A2: 1 | B2: السيرة النبوية | C2: لقاءات السيرة النبوية | D2: غزوة الأحزاب | F2: أحداث ما بعد غزوة الأحزاب | H2: صوتي | I2: 2021-11-12 | J2: فتح في تليجرام
A3: 2 | B3: السيرة النبوية | C3: لقاءات السيرة النبوية | D3: غزوة الأحزاب | F3: لقاء الخميس | G3: موعدنا العشاء بمشيئة الله بمسجد فجر الإسلام مع درس سيرة الحبيب صلى الله عليه وسلم أحداث ما بعد غزوة الأحزاب | H3: صوتي | I3: 2021-11-18 | J3: فتح في تليجرام
A4: 3 | B4: السيرة النبوية | C4: لقاءات السيرة النبوية | D4: غزوة بني قريظة | F4: غزوة بني قريظة (2021-11-12) | H4: صوتي | I4: 2021-11-12 | J4: فتح في تليجرام
A5: 4 | B5: السيرة النبوية | C5: لقاءات السيرة النبوية | D5: غزوة بني لحيان | F5: غزوة بني لحيان - سرية الخبط وحوت العنبر | H5: صوتي | I5: 2021-12-02 | J5: فتح في تليجرام
A6: 5 | B6: السيرة النبوية | C6: لقاءات السيرة النبوية | D6: غزوة بني المصطلق (المريسيع) | E6: 1 | F6: غزوة بني المصطلق (المريسيع) - الدرس 1 | H6: صوتي | I6: 2021-12-09 | J6: فتح في تليجرام
A7: 6 | B7: السيرة النبوية | C7: لقاءات السيرة النبوية | D7: غزوة بني المصطلق (المريسيع) | F7: وقفات مع غزوة بني المصطلق-المريسيع | H7: صوتي | I7: 2022-04-10 | J7: فتح في تليجرام
A8: 7 | B8: السيرة النبوية | C8: لقاءات السيرة النبوية | D8: غزوة بني المصطلق (المريسيع) | F8: وقفات مع غزوة بني المصطلق-المريسيع | H8: صوتي | I8: 2022-04-10 | J8: فتح في تليجرام
A9: 8 | B9: السيرة النبوية | C9: لقاءات السيرة النبوية | D9: غزوة بني المصطلق (المريسيع) | F9: وقفات مع غزوة بني المصطلق-المريسيع-الافك | H9: صوتي | I9: 2022-04-19 | J9: فتح في تليجرام
A10: 9 | B10: السيرة النبوية | C10: لقاءات السيرة النبوية | D10: غزوة بني المصطلق (المريسيع) | E10: 1 | F10: غزوة المريسيع - تأملات في آيات سورة النور-1 | H10: صوتي | I10: 2022-05-13 | J10: فتح في تليجرام
A11: 10 | B11: السيرة النبوية | C11: لقاءات السيرة النبوية | D11: غزوة بني المصطلق (المريسيع) | E11: 2 | F11: غزوة المريسيع - تأملات في آيات سورة النور-2 | H11: صوتي | I11: 2022-05-20 | J11: فتح في تليجرام
A12: 11 | B12: السيرة النبوية | C12: لقاءات السيرة النبوية | D12: غزوة بني المصطلق (المريسيع) | F12: تأملات في آيات غزوة بني المصطلق وحادثة إلافك | H12: صوتي | I12: 2022-06-02 | J12: فتح في تليجرام
A13: 12 | B13: السيرة النبوية | C13: لقاءات السيرة النبوية | D13: غزوة بني المصطلق (المريسيع) | F13: غزوة المريسيع و خاتمة حادثة الإفك | H13: صوتي | I13: 2022-07-22 | J13: فتح في تليجرام
A14: 13 | B14: السيرة النبوية | C14: لقاءات السيرة النبوية | D14: لقاءات متفرقة | F14: لقاء السيرة النبوية | H14: صوتي | I14: 2021-12-23 | J14: فتح في تليجرام
A15: 14 | B15: السيرة النبوية | C15: لقاءات السيرة النبوية | D15: لقاءات متفرقة | F15: وقفات مع يوم بئر معونة | H15: صوتي | I15: 2022-04-07 | J15: فتح في تليجرام
A16: 15 | B16: السيرة النبوية | C16: لقاءات السيرة النبوية | D16: لقاءات متفرقة | F16: تأملات في آيات حادثة إلافك، بيان مخططات أعداء الأمة في نشر الفاحشة | H16: صوتي | I16: 2022-06-09 | J16: فتح في تليجرام
A17: 16 | B17: السيرة النبوية | C17: لقاءات السيرة النبوية | D17: لقاءات متفرقة | F17: وقفات مع العهود مع اليهود | G17: تاريخ بيت المقدس من البناء حتى يومنا هذا. | H17: صوتي | I17: 2023-11-23 | J17: فتح في تليجرام
A18: 17 | B18: السيرة النبوية | C18: لقاءات السيرة النبوية | D18: لقاءات متفرقة | F18: عمرة القضاء | H18: صوتي | I18: 2023-12-09 | J18: فتح في تليجرام
A19: 18 | B19: السيرة النبوية | C19: لقاءات السيرة النبوية | D19: لقاءات متفرقة | F19: تأملات ووقفات إيمانية في غزوات النبي صلى الله عليه وسلم | H19: صوتي | I19: 2026-06-18 | J19: فتح في تليجرام
A20: 19 | B20: السيرة النبوية | C20: لقاءات السيرة النبوية | D20: لقاءات متفرقة | F20: البيت النبوي، ختام السيرة المطهرة | H20: صوتي | I20: 2026-10-29 | J20: فتح في تليجرام
A21: 20 | B21: السيرة النبوية | C21: لقاءات السيرة النبوية | D21: حادثة الإفك | E21: 1 | F21: حادثة الافك-1 | H21: صوتي | I21: 2021-12-30 | J21: فتح في تليجرام
A22: 21 | B22: السيرة النبوية | C22: لقاءات السيرة النبوية | D22: حادثة الإفك | F22: حادثة الافك | H22: صوتي | I22: 2022-01-06 | J22: فتح في تليجرام
A23: 22 | B23: السيرة النبوية | C23: لقاءات السيرة النبوية | D23: حادثة الإفك | F23: حادثة الإفك (2022-01-20) | H23: صوتي | I23: 2022-01-20 | J23: فتح في تليجرام
A24: 23 | B24: السيرة النبوية | C24: لقاءات السيرة النبوية | D24: حادثة الإفك | E24: 2 | F24: حادثة الإفك - الدرس 2 | H24: صوتي | I24: 2022-02-10 | J24: فتح في تليجرام
A25: 24 | B25: السيرة النبوية | C25: لقاءات السيرة النبوية | D25: غزوة أحد | E25: 1 | F25: وقفات مع يوم احد. - 1 | H25: صوتي | I25: 2022-04-01 | J25: فتح في تليجرام
A26: 25 | B26: السيرة النبوية | C26: لقاءات السيرة النبوية | D26: غزوة أحد | E26: 2 | F26: وقفات مع يوم احد. - 2 | H26: صوتي | I26: 2022-04-03 | J26: فتح في تليجرام
A27: 26 | B27: السيرة النبوية | C27: لقاءات السيرة النبوية | D27: غزوة أحد | E27: 3 | F27: وقفات مع يوم احد. - 3 | H27: صوتي | I27: 2022-04-04 | J27: فتح في تليجرام
A28: 27 | B28: السيرة النبوية | C28: لقاءات السيرة النبوية | D28: غزوة أحد | E28: 4 | F28: لقاءات السيرة النبوية.. وقفات مع يوم احد. - 4 | H28: صوتي | I28: 2022-04-04 | J28: فتح في تليجرام
A29: 28 | B29: السيرة النبوية | C29: لقاءات السيرة النبوية | D29: غزوة أحد | E29: 5 | F29: وقفات مع يوم احد. - 5 | H29: صوتي | I29: 2022-04-05 | J29: فتح في تليجرام
A30: 29 | B30: السيرة النبوية | C30: لقاءات السيرة النبوية | D30: غزوة تبوك | F30: نحن في تبوك | H30: صوتي | I30: 2022-04-08 | J30: فتح في تليجرام
A31: 30 | B31: السيرة النبوية | C31: لقاءات السيرة النبوية | D31: غزوة تبوك | E31: 1 | F31: غزوة تبوك - الدرس 1 | G31: غزوة تبوك-1. | H31: صوتي | I31: 2024-11-29 | J31: فتح في تليجرام
A32: 31 | B32: السيرة النبوية | C32: لقاءات السيرة النبوية | D32: غزوة تبوك | E32: 2 | F32: غزوة تبوك - الدرس 2 | G32: غزوة تبوك-2. | H32: صوتي | I32: 2024-12-10 | J32: فتح في تليجرام
A33: 32 | B33: السيرة النبوية | C33: لقاءات السيرة النبوية | D33: غزوة تبوك | E33: 3 | F33: غزوة تبوك - الدرس 3 | G33: غزوة تبوك-3. | H33: صوتي | I33: 2025-01-06 | J33: فتح في تليجرام
A34: 33 | B34: السيرة النبوية | C34: لقاءات السيرة النبوية | D34: غزوة تبوك | E34: 4 | F34: غزوة تبوك - الدرس 4 | G34: غزوة تبوك-4. | H34: صوتي | I34: 2025-01-06 | J34: فتح في تليجرام
A35: 34 | B35: السيرة النبوية | C35: لقاءات السيرة النبوية | D35: غزوة تبوك | E35: 5 | F35: غزوة تبوك - الدرس 5 | G35: غزوة تبوك-5. | H35: صوتي | I35: 2025-01-06 | J35: فتح في تليجرام
A36: 35 | B36: السيرة النبوية | C36: لقاءات السيرة النبوية | D36: غزوة تبوك | E36: 5 | F36: غزوة تبوك - الدرس 5 | G36: غزوة تبوك-5. | H36: صوتي | I36: 2025-01-26 | J36: فتح في تليجرام
A37: 36 | B37: السيرة النبوية | C37: لقاءات السيرة النبوية | D37: غزوة تبوك | E37: 6 | F37: العهود والمواثيق التي نزلت براءة بأحكامها | G37: غزوة تبوك-6. | H37: صوتي | I37: 2025-04-15 | J37: فتح في تليجرام
A38: 37 | B38: السيرة النبوية | C38: لقاءات السيرة النبوية | D38: غزوة تبوك | E38: 7 | F38: العهود والمواثيق التي نزلت براءة بأحكامها-2 | G38: غزوة تبوك-7. | H38: صوتي | I38: 2025-04-28 | J38: فتح في تليجرام
A39: 38 | B39: السيرة النبوية | C39: لقاءات السيرة النبوية | D39: غزوة تبوك | E39: 8 | F39: العهود والمواثيق التي نزلت براءة بأحكامها-3 | G39: غزوة تبوك-8. | H39: صوتي | I39: 2025-05-01 | J39: فتح في تليجرام
A40: 39 | B40: السيرة النبوية | C40: لقاءات السيرة النبوية | D40: غزوة تبوك | E40: 9 | F40: العهود والمواثيق التي نزلت براءة بأحكامها-4 | G40: غزوة تبوك-9. | H40: صوتي | I40: 2025-05-11 | J40: فتح في تليجرام
...

Sheet الحديث
A1: م | B1: التصنيف | C1: السلسلة | D1: الكتاب / الباب | E1: رقم الدرس | F1: عنوان الدرس | G1: الموضوعات | H1: النوع | I1: التاريخ | J1: الرابط
A2: 1 | B2: الحديث | C2: شرح البيقونية في مصطلح الحديث (دورة مصطلح الحديث) | F2: متن المنظومة البيقونية (PDF) | H2: PDF | I2: 2022-05-24 | J2: فتح في تليجرام
A3: 2 | B3: الحديث | C3: شرح البيقونية في مصطلح الحديث (دورة مصطلح الحديث) | E3: 1 | F3: شرح البيقونية - المجلس الأول | H3: صوتي | I3: 2022-05-24 | J3: فتح في تليجرام
A4: 3 | B4: الحديث | C4: شرح البيقونية في مصطلح الحديث (دورة مصطلح الحديث) | E4: 2 | F4: شرح البيقونية - المجلس الثاني | H4: صوتي | I4: 2022-05-24 | J4: فتح في تليجرام
A5: 4 | B5: الحديث | C5: شرح البيقونية في مصطلح الحديث (دورة مصطلح الحديث) | F5: شرح البيقونية في مصطلح الحديث (دورة مصطلح الحديث) (تابع) | H5: فيديو | I5: 2022-05-24 | J5: فتح في تليجرام
A6: 5 | B6: الحديث | C6: شرح البيقونية في مصطلح الحديث (دورة مصطلح الحديث) | E6: 3 | F6: شرح البيقونية - المجلس الثالث | H6: صوتي | I6: 2022-05-24 | J6: فتح في تليجرام
A7: 6 | B7: الحديث | C7: شرح البيقونية في مصطلح الحديث (دورة مصطلح الحديث) | E7: 4 | F7: شرح البيقونية - المجلس الرابع | H7: صوتي | I7: 2022-05-24 | J7: فتح في تليجرام
A8: 7 | B8: الحديث | C8: شرح البيقونية في مصطلح الحديث (دورة مصطلح الحديث) | E8: 5 | F8: شرح البيقونية - المجلس الخامس | H8: صوتي | I8: 2022-05-24 | J8: فتح في تليجرام

Sheet شروح السنة
A1: م | B1: التصنيف | C1: السلسلة | D1: الكتاب / الباب | E1: رقم الدرس | F1: عنوان الدرس | G1: الموضوعات | H1: النوع | I1: التاريخ | J1: الرابط
A2: 1 | B2: شروح السنة | C2: شرح السلسلة الصحيحة (كاملة) | D2: الأخلاق والبر والصلة | E2: 71 | F2: من أخلاقه صلى الله عليه وسلم | H2: صوتي | I2: 2021-11-12 | J2: فتح في تليجرام
A3: 2 | B3: شروح السنة | C3: شرح السلسلة الصحيحة (كاملة) | D3: الأخلاق والبر والصلة | E3: 72 | F3: مواقف غيرة ازواج النبي صفية وعائشة وزينب في سفر حجة الوداع | H3: صوتي | I3: 2021-11-13 | J3: فتح في تليجرام
A4: 3 | B4: شروح السنة | C4: شرح السلسلة الصحيحة (كاملة) | D4: الأخلاق والبر والصلة | E4: 73 | F4: جملة من الآداب والسنن عند دخول الليل في البيت ومع الاطفال | H4: صوتي | I4: 2021-11-15 | J4: فتح في تليجرام
A5: 4 | B5: شروح السنة | C5: شرح السلسلة الصحيحة (كاملة) | D5: الأخلاق والبر والصلة | E5: 74 | F5: من أخلاقه مع احفاده | H5: صوتي | I5: 2021-11-18 | J5: فتح في تليجرام
A6: 5 | B6: شروح السنة | C6: شرح السلسلة الصحيحة (كاملة) | D6: الأخلاق والبر والصلة | E6: 75 | F6: مخموم القلب | H6: صوتي | I6: 2021-11-19 | J6: فتح في تليجرام
A7: 6 | B7: شروح السنة | C7: شرح السلسلة الصحيحة (كاملة) | D7: الأخلاق والبر والصلة | E7: 76 | F7: حكم اللحوم المستوردة والذبائح | G7: تغيير حدود الأرض • اللواط وحقوق المثليين عند الغرب. | H7: صوتي | I7: 2021-11-20 | J7: فتح في تليجرام
A8: 7 | B8: شروح السنة | C8: شرح السلسلة الصحيحة (كاملة) | D8: الأخلاق والبر والصلة | E8: 77 | F8: جود ابي طلحه وزوجه الرميساء | H8: صوتي | I8: 2021-11-21 | J8: فتح في تليجرام
A9: 8 | B9: شروح السنة | C9: شرح السلسلة الصحيحة (كاملة) | D9: الأخلاق والبر والصلة | E9: 78 | F9: لو أن رجلين دخلا في الإسلام فاهتجرا | H9: صوتي | I9: 2021-11-22 | J9: فتح في تليجرام
A10: 9 | B10: شروح السنة | C10: شرح السلسلة الصحيحة (كاملة) | D10: الأخلاق والبر والصلة | E10: 79 | F10: لو رايتموني وابليس | H10: صوتي | I10: 2021-11-23 | J10: فتح في تليجرام
A11: 10 | B11: شروح السنة | C11: شرح السلسلة الصحيحة (كاملة) | D11: الأخلاق والبر والصلة | E11: 80 | F11: اعجل الأعمال الصالحة ثوابا، اعجل المعاصي عقوبة | H11: صوتي | I11: 2021-11-24 | J11: فتح في تليجرام
A12: 11 | B12: شروح السنة | C12: شرح السلسلة الصحيحة (كاملة) | D12: الأخلاق والبر والصلة | E12: 81 | F12: فضيلة تطهير وتطييب المسجد | H12: صوتي | I12: 2021-11-25 | J12: فتح في تليجرام
A13: 12 | B13: شروح السنة | C13: شرح السلسلة الصحيحة (كاملة) | D13: الأخلاق والبر والصلة | E13: 82 | F13: ما أخاف على أمَّتي إلَّا ثلاثًا : شُحٌّ مُطاعٌ ، وهوًى مُتَّبعٌ ، وإمامُ ضلالٍ | G13: تذكرة بآداب وسنن الجمعة. | H13: صوتي | I13: 2021-11-26 | J13: فتح في تليجرام
A14: 13 | B14: شروح السنة | C14: شرح السلسلة الصحيحة (كاملة) | D14: الأخلاق والبر والصلة | E14: 83 | F14: مَا اسْتَكْبَرَ مَنْ أَكَلَ مَعَهُ خَادِمُهُ، وَرَكِبَ الْحِمَارَ بِالأَسْوَاقِ، وَاعْتَقَلَ الشَّاةَ فَحَلَبَهَا" | H14: صوتي | I14: 2021-11-27 | J14: فتح في تليجرام
A15: 14 | B15: شروح السنة | C15: شرح السلسلة الصحيحة (كاملة) | D15: الأخلاق والبر والصلة | E15: 84 | F15: مَا اظن فلانا وفلانا يعرفان من ديننا شيئا" | H15: صوتي | I15: 2021-11-28 | J15: فتح في تليجرام
A16: 15 | B16: شروح السنة | C16: شرح السلسلة الصحيحة (كاملة) | D16: الأخلاق والبر والصلة | E16: 85 | F16: آداب النصيحة | G16: مَا تعدون الرقوب فيكم.. • ابخل الناس... | H16: صوتي | I16: 2021-11-29 | J16: فتح في تليجرام
A17: 16 | B17: شروح السنة | C17: شرح السلسلة الصحيحة (كاملة) | D17: الأخلاق والبر والصلة | E17: 86 | F17: أفضل الأعمال | G17: أبغض خلق الي رسول الله • اعجل الذنوب عقوبة | H17: صوتي | I17: 2021-11-30 | J17: فتح في تليجرام
A18: 17 | B18: شروح السنة | C18: شرح السلسلة الصحيحة (كاملة) | D18: الأخلاق والبر والصلة | E18: 87 | F18: فضل الزيارة في الله | H18: صوتي | I18: 2021-12-01 | J18: فتح في تليجرام
A19: 18 | B19: شروح السنة | C19: شرح السلسلة الصحيحة (كاملة) | D19: الأخلاق والبر والصلة | E19: 88 | F19: الأعمال الخمسة المنجية مع الايمان | H19: صوتي | I19: 2021-12-02 | J19: فتح في تليجرام
A20: 19 | B20: شروح السنة | C20: شرح السلسلة الصحيحة (كاملة) | D20: الأخلاق والبر والصلة | E20: 89 | F20: اليمين الغموس-عاقبة الكبر-من حقوق الجار | H20: صوتي | I20: 2021-12-03 | J20: فتح في تليجرام
A21: 20 | B21: شروح السنة | C21: شرح السلسلة الصحيحة (كاملة) | D21: الأخلاق والبر والصلة | E21: 90 | F21: فضل سكني المدينة -الاطلاع على عورات البيوت | H21: صوتي | I21: 2021-12-04 | J21: فتح في تليجرام
A22: 21 | B22: شروح السنة | C22: شرح السلسلة الصحيحة (كاملة) | D22: الأخلاق والبر والصلة | E22: 91 | F22: اخلاق المؤمنين الهينة اللينة | H22: صوتي | I22: 2021-12-05 | J22: فتح في تليجرام
A23: 22 | B23: شروح السنة | C23: شرح السلسلة الصحيحة (كاملة) | D23: الأخلاق والبر والصلة | E23: 92 | F23: عطاء النبي للانصار-هلاك الوعول وظهور التحوت | H23: صوتي | I23: 2021-12-06 | J23: فتح في تليجرام
A24: 23 | B24: شروح السنة | C24: شرح السلسلة الصحيحة (كاملة) | D24: الأخلاق والبر والصلة | E24: 93 | F24: أعمال في سبيل الله- لا اجر الا بحسبة ولا عمل الا بنية | H24: صوتي | I24: 2021-12-07 | J24: فتح في تليجرام
A25: 24 | B25: شروح السنة | C25: شرح السلسلة الصحيحة (كاملة) | D25: الأخلاق والبر والصلة | E25: 94 | F25: موقف ابن سلول وابنه عبدالله | H25: صوتي | I25: 2021-12-08 | J25: فتح في تليجرام
A26: 25 | B26: شروح السنة | C26: شرح السلسلة الصحيحة (كاملة) | D26: الأخلاق والبر والصلة | E26: 95 | F26: لا يتم بعد احتلام-تزكية الصحابة أنفسهم من الكبر | H26: صوتي | I26: 2021-12-09 | J26: فتح في تليجرام
A27: 26 | B27: شروح السنة | C27: شرح السلسلة الصحيحة (كاملة) | D27: الأخلاق والبر والصلة | E27: 96 | F27: استقامة القلب-ذو الوجهين-أثقل خلقين في الميزان | H27: صوتي | I27: 2021-12-10 | J27: فتح في تليجرام
A28: 27 | B28: شروح السنة | C28: شرح السلسلة الصحيحة (كاملة) | D28: الأخلاق والبر والصلة | E28: 97 | F28: تودد النبي لعائشة أحكام الغناء ومايجوز منه | H28: صوتي | I28: 2021-12-11 | J28: فتح في تليجرام
A29: 28 | B29: شروح السنة | C29: شرح السلسلة الصحيحة (كاملة) | E29: 1 | F29: شرح أحاديث الأحكام /فقه الطهارة - 1 | H29: صوتي | I29: 2021-11-14 | J29: فتح في تليجرام
A30: 29 | B30: شروح السنة | C30: شرح السلسلة الصحيحة (كاملة) | E30: 2 | F30: شرح أحاديث الأحكام /فقه الطهارة - 2 | H30: صوتي | I30: 2021-11-14 | J30: فتح في تليجرام
A31: 30 | B31: شروح السنة | C31: شرح السلسلة الصحيحة (كاملة) | E31: 3 | F31: فقه الطهارة -3 | G31: شرح أحاديث الأحكام | H31: صوتي | I31: 2021-11-14 | J31: فتح في تليجرام
A32: 31 | B32: شروح السنة | C32: شرح السلسلة الصحيحة (كاملة) | E32: 4 | F32: فقه الطهارة - 4 | H32: صوتي | I32: 2021-11-14 | J32: فتح في تليجرام
A33: 32 | B33: شروح السنة | C33: شرح السلسلة الصحيحة (كاملة) | E33: 5 | F33: فقه الطهارة - 5 | H33: صوتي | I33: 2021-11-14 | J33: فتح في تليجرام
A34: 33 | B34: شروح السنة | C34: شرح السلسلة الصحيحة (كاملة) | E34: 6 | F34: فقه الطهارة - 6 | H34: صوتي | I34: 2021-11-14 | J34: فتح في تليجرام
A35: 34 | B35: شروح السنة | C35: شرح السلسلة الصحيحة (كاملة) | E35: 7 | F35: اسئلة شرح أحاديث الأحكام من | G35: فقه الطهارة - 7 | H35: صوتي | I35: 2021-11-14 | J35: فتح في تليجرام
A36: 35 | B36: شروح السنة | C36: شرح السلسلة الصحيحة (كاملة) | E36: 7 | F36: فقه الطهارة - 7 ج2 | H36: صوتي | I36: 2021-11-14 | J36: فتح في تليجرام
A37: 36 | B37: شروح السنة | C37: شرح السلسلة الصحيحة (كاملة) | E37: 8 | F37: اسئلة شرح أحاديث الأحكام من | G37: فقه الطهارة - 8 | H37: صوتي | I37: 2021-11-14 | J37: فتح في تليجرام
A38: 37 | B38: شروح السنة | C38: شرح السلسلة الصحيحة (كاملة) | E38: 9 | F38: اسئلة شرح أحاديث الأحكام من | G38: فقه الطهارة - 9 | H38: صوتي | I38: 2021-11-14 | J38: فتح في تليجرام
A39: 38 | B39: شروح السنة | C39: شرح السلسلة الصحيحة (كاملة) | F39: درس مراجعة فقه الطهارة | H39: صوتي | I39: 2021-11-14 | J39: فتح في تليجرام
A40: 39 | B40: شروح السنة | C40: شرح السلسلة الصحيحة (كاملة) | E40: 1 | F40: للألباني مجردة عن التخريج-الطهارة1.pdf | H40: PDF | I40: 2021-11-14 | J40: فتح في تليجرام
...

Sheet العقيدة
A1: م | B1: التصنيف | C1: السلسلة | D1: الكتاب / الباب | E1: رقم الدرس | F1: عنوان الدرس | G1: الموضوعات | H1: النوع | I1: التاريخ | J1: الرابط
A2: 1 | B2: العقيدة | C2: شرح أصول الإيمان | F2: شرح أصول الإيمان | H2: صوتي | I2: 2022-06-11 | J2: فتح في تليجرام
A3: 2 | B3: العقيدة | C3: شرح العقيدة الواسطية | E3: 2 | F3: المقدمه درس 2 | H3: صوتي | I3: 2022-02-10 | J3: فتح في تليجرام
A4: 3 | B4: العقيدة | C4: شرح العقيدة الواسطية | E4: 3 | F4: شرح العقيدة الواسطية - الدرس 3 | H4: صوتي | I4: 2022-03-16 | J4: فتح في تليجرام
A5: 4 | B5: العقيدة | C5: شرح العقيدة الواسطية | E5: 4 | F5: شرح العقيدة الواسطية - الدرس 4 | H5: صوتي | I5: 2022-03-16 | J5: فتح في تليجرام
A6: 5 | B6: العقيدة | C6: شرح العقيدة الواسطية | E6: 5 | F6: شرح العقيدة الواسطية - الدرس 5 | H6: صوتي | I6: 2022-03-17 | J6: فتح في تليجرام
A7: 6 | B7: العقيدة | C7: شرح العقيدة الواسطية | E7: 6 | F7: الإيمان بالرسل والايمان بالبعث واليوم الآخر 6 | H7: صوتي | I7: 2022-05-21 | J7: فتح في تليجرام
A8: 7 | B8: العقيدة | C8: شرح العقيدة الواسطية | E8: 7 | F8: الإيمان بالاسماء و الصفات 7 | H8: صوتي | I8: 2022-05-21 | J8: فتح في تليجرام
A9: 8 | B9: العقيدة | C9: شرح العقيدة الواسطية | E9: 8 | F9: 8 الإيمان بالاسماء والصفات.-شروط التأويل الصحيح | H9: صوتي | I9: 2022-05-22 | J9: فتح في تليجرام
A10: 9 | B10: العقيدة | C10: شرح العقيدة الواسطية | E10: 9 | F10: 9 - تابع قواعد الإيمان بالاسماء والصفات | H10: صوتي | I10: 2022-05-22 | J10: فتح في تليجرام
A11: 10 | B11: العقيدة | C11: شرح العقيدة الواسطية | E11: 10 | F11: 10 تابع قواعد الإيمان بالاسماء والصفات-إثبات الأسماء والصفات من القرآن الكريم | H11: صوتي | I11: 2022-05-22 | J11: فتح في تليجرام
A12: 11 | B12: العقيدة | C12: شرح العقيدة الواسطية | E12: 11 | F12: تابع قواعد الإيمان بالاسماء والصفات-تابع إثبات الأسماء والصفات من القرآن الكريم.درس 11، آية الكرسي | H12: صوتي | I12: 2022-09-24 | J12: فتح في تليجرام
A13: 12 | B13: العقيدة | C13: شرح العقيدة الواسطية | E13: 12 | F13: تابع قواعد الإيمان بالاسماء والصفات-تابع إثبات الأسماء والصفات من القرآن الكريم.درس 12، الأسماء الأربعة (الأول، الآخر، الظاهر، الباطن) | H13: صوتي | I13: 2022-09-25 | J13: فتح في تليجرام
A14: 13 | B14: العقيدة | C14: شرح العقيدة الواسطية | E14: 13 | F14: تابع قواعد الإيمان بالاسماء والصفات-تابع إثبات الأسماء والصفات من القرآن الكريم.درس 13، تابع الأسماء الأربعة (الأول، الآخر، الظاهر، الباطن) | H14: صوتي | I14: 2022-10-08 | J14: فتح في تليجرام
... A24: 23 | B24: العقيدة | C24: شرح العقيدة الواسطية | E24: 23 | F24: تابع قواعد الإيمان بالاسماء والصفات-تابع إثبات الأسماء والصفات من القرآن الكريم.درس 23، الصفات (صفة الكلام ) | H24: صوتي | I24: 2022-12-20 | J24: فتح في تليجرام
A25: 24 | B25: العقيدة | C25: شرح العقيدة الواسطية | E25: 24 | F25: تابع قواعد الإيمان بالاسماء والصفات-تابع إثبات الأسماء والصفات من القرآن الكريم.درس 24، الصفات (صفة رؤية المؤمنين ربهم- ملخص أصول الإيمان في الأسماء والصفات) | G25: الاستدلال على الأسماء والصفات من السنة (حجية السنة واخبار الآحاد في الاعتقاد - صفة النزول- صفة الفرح- صفة الضحك-صفة العجب - صفة الرجل والقدم- صفة النداء والصوت). | H25: صوتي | I25: 2022-12-20 | J25: فتح في تليجرام
A26: 25 | B26: العقيدة | C26: شرح العقيدة الواسطية | E26: 25 | F26: درس 25، الاستدلال على الأسماء والصفات من السنة (صفة العلو والفوقية) | H26: صوتي | I26: 2023-01-17 | J26: فتح في تليجرام
A27: 26 | B27: العقيدة | C27: شرح العقيدة الواسطية | E27: 26 | F27: درس 26، الاستدلال على الأسماء والصفات من السنة (صفة المعية) | H27: صوتي | I27: 2023-01-20 | J27: فتح في تليجرام
A28: 27 | B28: العقيدة | C28: شرح العقيدة الواسطية | E28: 27 | F28: درس 27، أهل السنة وسط بين الفرق | H28: صوتي | I28: 2023-01-25 | J28: فتح في تليجرام
A29: 28 | B29: العقيدة | C29: شرح العقيدة الواسطية | E29: 28 | F29: درس 28، أهل السنة وسط بين الفرق (الجبرية، القدرية)، (الوعيدية والمرجئة) | H29: صوتي | I29: 2023-02-27 | J29: فتح في تليجرام
A30: 29 | B30: العقيدة | C30: شرح العقيدة الواسطية | E30: 29 | F30: درس 29، أهل السنة وسط بين الفرق (الوعيدية والمرجئة)، (الرافضة و الخوارج)، الإيمان باليوم الآخر | H30: صوتي | I30: 2023-02-28 | J30: فتح في تليجرام
A31: 30 | B31: العقيدة | C31: شرح العقيدة الواسطية | E31: 30 | F31: درس 30، تابع الإيمان باليوم الآخر | H31: صوتي | I31: 2023-03-03 | J31: فتح في تليجرام
A32: 31 | B32: العقيدة | C32: شرح العقيدة الواسطية | E32: 31 | F32: درس 31، مسائل إلايمان والكفر | H32: صوتي | I32: 2023-03-18 | J32: فتح في تليجرام
A33: 32 | B33: العقيدة | C33: شرح العقيدة الواسطية | E33: 32 | F33: درس 32، العقيدة فى الصحابة وال البيت، المعجزات والكرامات، أصول منهج أهل السنة والجماعة وخصالهم | H33: صوتي | I33: 2023-03-20 | J33: فتح في تليجرام
A34: 33 | B34: العقيدة | C34: شرح لمعة الاعتقاد لابن قدامة | E34: 1 | F34: شرح لمعة الاعتقاد لابن قدامة - الدرس 1 | H34: صوتي | I34: 2023-01-27 | J34: فتح في تليجرام
A35: 34 | B35: العقيدة | C35: شرح لمعة الاعتقاد لابن قدامة | E35: 1 | F35: 1 ج2 | H35: صوتي | I35: 2023-01-29 | J35: فتح في تليجرام
A36: 35 | B36: العقيدة | C36: شرح لمعة الاعتقاد لابن قدامة | E36: 2 | F36: شرح لمعة الاعتقاد لابن قدامة - الدرس 2 | H36: صوتي | I36: 2023-01-29 | J36: فتح في تليجرام
A37: 36 | B37: العقيدة | C37: شرح لمعة الاعتقاد لابن قدامة | E37: 2 | F37: شرح لمعة الاعتقاد لابن قدامة 2 ج2 | H37: صوتي | I37: 2023-01-29 | J37: فتح في تليجرام
A38: 37 | B38: العقيدة | C38: شرح لمعة الاعتقاد لابن قدامة | E38: 3 | F38: شرح لمعة الاعتقاد لابن قدامة - الدرس 3 | H38: صوتي | I38: 2023-01-30 | J38: فتح في تليجرام
A39: 38 | B39: العقيدة | C39: شرح اعتقاد أهل السنة | F39: مراجعة عقيدة شرح المنة-الإيمان بالله.-حل الاختبار | H39: صوتي | I39: 2022-08-03 | J39: فتح في تليجرام
A40: 39 | B40: العقيدة | C40: شرح اعتقاد أهل السنة | F40: عقيدة شرح المنة | G40: الإيمان بالملائكة-الايمان بالكتب | H40: صوتي | I40: 2022-08-18 | J40: فتح في تليجرام
A41: 40 | B41: العقيدة | C41: شرح اعتقاد أهل السنة | E41: 1 | F41: عقيدة- شرح المنة - القضاء والقدر - 1 | H41: صوتي | I41: 2022-09-23 | J41: فتح في تليجرام
A42: 41 | B42: العقيدة | C42: شرح اعتقاد أهل السنة | E42: 2 | F42: عقيدة- شرح المنة - القضاء والقدر - 2 | H42: صوتي | I42: 2022-10-05 | J42: فتح في تليجرام
A43: 42 | B43: العقيدة | C43: شرح اعتقاد أهل السنة | E43: 3 | F43: القضاء والقدر - 3 | H43: صوتي | I43: 2022-10-07 | J43: فتح في تليجرام
A44: 43 | B44: العقيدة | C44: شرح اعتقاد أهل السنة | E44: 4 | F44: القضاء والقدر - 4 | H44: صوتي | I44: 2022-10-28 | J44: فتح في تليجرام
A45: 44 | B45: العقيدة | C45: شرح اعتقاد أهل السنة | E45: 5 | F45: القضاء والقدر - 5 | H45: صوتي | I45: 2022-11-02 | J45: فتح في تليجرام
A46: 45 | B46: العقيدة | C46: شرح اعتقاد أهل السنة | E46: 1 | F46: العقيدة فى الصحابة 1 | H46: صوتي | I46: 2022-11-07 | J46: فتح في تليجرام
A47: 46 | B47: العقيدة | C47: شرح اعتقاد أهل السنة | E47: 2 | F47: العقيدة فى الصحابة 2 | H47: صوتي | I47: 2022-11-18 | J47: فتح في تليجرام
A48: 47 | B48: العقيدة | C48: شرح اعتقاد أهل السنة | E48: 3 | F48: العقيدة فى الصحابة 3 | H48: صوتي | I48: 2022-11-25 | J48: فتح في تليجرام
A49: 48 | B49: العقيدة | C49: شرح العقيدة الميسرة للنساء (متجدد) | E49: 1 | F49: شرح العقيدة للنساء - المنة -1 | G49: الأسماء والصفات - 1 | H49: صوتي | I49: 2022-09-02 | J49: فتح في تليجرام
...

Sheet الفقه
A1: م | B1: التصنيف | C1: السلسلة | D1: الكتاب / الباب | E1: رقم الدرس | F1: عنوان الدرس | G1: الموضوعات | H1: النوع | I1: التاريخ | J1: الرابط
A2: 1 | B2: الفقه | C2: شرح الفقه الميسر | D2: الطهارة | E2: 1 | F2: الطهارة - الدرس 1 | H2: صوتي | I2: 2022-08-27 | J2: فتح في تليجرام
A3: 2 | B3: الفقه | C3: شرح الفقه الميسر | D3: الطهارة | E3: 2 | F3: الطهارة - الدرس 2 | H3: صوتي | I3: 2022-09-09 | J3: فتح في تليجرام
A4: 3 | B4: الفقه | C4: شرح الفقه الميسر | D4: الطهارة | E4: 3 | F4: كتاب الطهارة -3 (باب الآنية) | H4: صوتي | I4: 2022-09-24 | J4: فتح في تليجرام
A5: 4 | B5: الفقه | C5: شرح الفقه الميسر | D5: الطهارة | E5: 4 | F5: كتاب الطهارة -4 (باب قضاء الحاجة) | H5: صوتي | I5: 2022-10-15 | J5: فتح في تليجرام
